# `java`异常

## 异常的格式

示例的详细代码请参考 [链接](https://gitee.com/dexterleslie/demonstration/blob/master/demo-java/demo-java-assistant/src/test/java/com/future/demo/ExceptionTests.java#L10)

异常格式解析：

```bash
com.intellij.rt.junit.JUnitStarter -ideVersion5 -junit4 com.future.demo.ExceptionTests
# 异常的调用堆栈从下至上查看
java.lang.Exception: My customize exception with cause exception
	at com.future.demo.ExceptionTests.customizeExceptionWithCauseException(ExceptionTests.java:20)
	at com.future.demo.ExceptionTests.test(ExceptionTests.java:11)
	at sun.reflect.NativeMethodAccessorImpl.invoke0(Native Method)
	at sun.reflect.NativeMethodAccessorImpl.invoke(NativeMethodAccessorImpl.java:62)
	at sun.reflect.DelegatingMethodAccessorImpl.invoke(DelegatingMethodAccessorImpl.java:43)
	at java.lang.reflect.Method.invoke(Method.java:498)
	at org.junit.runners.model.FrameworkMethod$1.runReflectiveCall(FrameworkMethod.java:50)
	at org.junit.internal.runners.model.ReflectiveCallable.run(ReflectiveCallable.java:12)
	at org.junit.runners.model.FrameworkMethod.invokeExplosively(FrameworkMethod.java:47)
	at org.junit.internal.runners.statements.InvokeMethod.evaluate(InvokeMethod.java:17)
	at org.junit.runners.ParentRunner.runLeaf(ParentRunner.java:325)
	at org.junit.runners.BlockJUnit4ClassRunner.runChild(BlockJUnit4ClassRunner.java:78)
	at org.junit.runners.BlockJUnit4ClassRunner.runChild(BlockJUnit4ClassRunner.java:57)
	at org.junit.runners.ParentRunner$3.run(ParentRunner.java:290)
	at org.junit.runners.ParentRunner$1.schedule(ParentRunner.java:71)
	at org.junit.runners.ParentRunner.runChildren(ParentRunner.java:288)
	at org.junit.runners.ParentRunner.access$000(ParentRunner.java:58)
	at org.junit.runners.ParentRunner$2.evaluate(ParentRunner.java:268)
	at org.junit.runners.ParentRunner.run(ParentRunner.java:363)
	at org.junit.runner.JUnitCore.run(JUnitCore.java:137)
	at com.intellij.junit4.JUnit4IdeaTestRunner.startRunnerWithArgs(JUnit4IdeaTestRunner.java:69)
	at com.intellij.rt.junit.IdeaTestRunner$Repeater$1.execute(IdeaTestRunner.java:38)
	at com.intellij.rt.execution.junit.TestsRepeater.repeat(TestsRepeater.java:11)
	at com.intellij.rt.junit.IdeaTestRunner$Repeater.startRunnerWithArgs(IdeaTestRunner.java:35)
	at com.intellij.rt.junit.JUnitStarter.prepareStreamsAndStart(JUnitStarter.java:232)
	at com.intellij.rt.junit.JUnitStarter.main(JUnitStarter.java:55)
# Caused by是异常的中的cause异常，调用堆栈也是从下至上查看
Caused by: java.lang.Exception: My customize exception inner cause exception
	at com.future.demo.ExceptionTests.customizeExceptionReturnCauseException(ExceptionTests.java:29)
	at com.future.demo.ExceptionTests.customizeExceptionWithCauseException(ExceptionTests.java:18)
	... 25 more
20:50:42.640 [main] ERROR com.future.demo.ExceptionTests - My customize exception with cause exception
java.lang.Exception: My customize exception with cause exception
	at com.future.demo.ExceptionTests.customizeExceptionWithCauseException(ExceptionTests.java:20) ~[test-classes/:na]
	at com.future.demo.ExceptionTests.test(ExceptionTests.java:11) ~[test-classes/:na]
	at sun.reflect.NativeMethodAccessorImpl.invoke0(Native Method) ~[na:1.8.0_271]
	at sun.reflect.NativeMethodAccessorImpl.invoke(NativeMethodAccessorImpl.java:62) ~[na:1.8.0_271]
	at sun.reflect.DelegatingMethodAccessorImpl.invoke(DelegatingMethodAccessorImpl.java:43) ~[na:1.8.0_271]
	at java.lang.reflect.Method.invoke(Method.java:498) ~[na:1.8.0_271]
	at org.junit.runners.model.FrameworkMethod$1.runReflectiveCall(FrameworkMethod.java:50) [junit-4.12.jar:4.12]
	at org.junit.internal.runners.model.ReflectiveCallable.run(ReflectiveCallable.java:12) [junit-4.12.jar:4.12]
	at org.junit.runners.model.FrameworkMethod.invokeExplosively(FrameworkMethod.java:47) [junit-4.12.jar:4.12]
	at org.junit.internal.runners.statements.InvokeMethod.evaluate(InvokeMethod.java:17) [junit-4.12.jar:4.12]
	at org.junit.runners.ParentRunner.runLeaf(ParentRunner.java:325) [junit-4.12.jar:4.12]
	at org.junit.runners.BlockJUnit4ClassRunner.runChild(BlockJUnit4ClassRunner.java:78) [junit-4.12.jar:4.12]
	at org.junit.runners.BlockJUnit4ClassRunner.runChild(BlockJUnit4ClassRunner.java:57) [junit-4.12.jar:4.12]
	at org.junit.runners.ParentRunner$3.run(ParentRunner.java:290) [junit-4.12.jar:4.12]
	at org.junit.runners.ParentRunner$1.schedule(ParentRunner.java:71) [junit-4.12.jar:4.12]
	at org.junit.runners.ParentRunner.runChildren(ParentRunner.java:288) [junit-4.12.jar:4.12]
	at org.junit.runners.ParentRunner.access$000(ParentRunner.java:58) [junit-4.12.jar:4.12]
	at org.junit.runners.ParentRunner$2.evaluate(ParentRunner.java:268) [junit-4.12.jar:4.12]
	at org.junit.runners.ParentRunner.run(ParentRunner.java:363) [junit-4.12.jar:4.12]
	at org.junit.runner.JUnitCore.run(JUnitCore.java:137) [junit-4.12.jar:4.12]
	at com.intellij.junit4.JUnit4IdeaTestRunner.startRunnerWithArgs(JUnit4IdeaTestRunner.java:69) [junit-rt.jar:na]
	at com.intellij.rt.junit.IdeaTestRunner$Repeater$1.execute(IdeaTestRunner.java:38) [junit-rt.jar:na]
	at com.intellij.rt.execution.junit.TestsRepeater.repeat(TestsRepeater.java:11) [idea_rt.jar:na]
	at com.intellij.rt.junit.IdeaTestRunner$Repeater.startRunnerWithArgs(IdeaTestRunner.java:35) [junit-rt.jar:na]
	at com.intellij.rt.junit.JUnitStarter.prepareStreamsAndStart(JUnitStarter.java:232) [junit-rt.jar:na]
	at com.intellij.rt.junit.JUnitStarter.main(JUnitStarter.java:55) [junit-rt.jar:na]
Caused by: java.lang.Exception: My customize exception inner cause exception
	at com.future.demo.ExceptionTests.customizeExceptionReturnCauseException(ExceptionTests.java:29) ~[test-classes/:na]
	at com.future.demo.ExceptionTests.customizeExceptionWithCauseException(ExceptionTests.java:18) ~[test-classes/:na]
	... 25 common frames omitted
```

